2025-09-28 17:58:51 UTC
Linux-6.6.88-08507-gc5e3cc23fa55-x86_64-with-glibc2.36
Ren'Py 8.4.1.25072401

Early init took 249 ms
Loading error handling took 67 ms
Loading script took 338 ms
Loading save slot metadata took 44 ms
Loading persistent took 0 ms
Running init code took 150 ms
Loading analysis data took 15 ms
Analyze and compile ATL took 3 ms
Reloading save slot metadata took 2 ms
Backing up script files to '/home/winterhyacinths/.renpy/backups/northriff':
Dump and make backups took 145 ms
Cleaning cache took 0 ms
Making clean stores took 1 ms
Initial gc took 104 ms
DPI scale factor: 1.000000
Creating interface object took 2 ms
Init translation took 0 ms
Cleaning stores took 0 ms
Load screen analysis took 0 ms
Analyze screens took 26 ms
Save screen analysis took 34 ms
Save pyanalysis took 0 ms
Save bytecode took 47 ms
Running _start took 3 ms
Interface start took 1070 ms

Initializing gl2 renderer:
primary display bounds: (0, 0, 1136, 640)
swap interval: 1 frames
Windowed mode.
Vendor: 'Mesa/X.org'
Renderer: 'llvmpipe (LLVM 15.0.6, 128 bits)'
Version: '4.5 (Compatibility Profile) Mesa 22.3.6'
Display Info: <Info({'bitsize': 32, 'bytesize': 4, 'masks': (16711680, 65280, 255, 0), 'shifts': (16, 8, 0, 0), 'losses': (0, 0, 0, 8), 'current_w': 1136, 'current_h': 640, 'refresh_rate': 60, 'hw': False, 'wm': True, 'video_mem': 268435456, 'blit_hw': False, 'blit_hw_CC': False, 'blit_hw_A': False, 'blit_sw': False, 'blit_sw_CC': False, 'blit_sw_A': False})>
Screen sizes: virtual=(1920, 1080) physical=(956, 538) drawable=(956, 538)
Maximum texture size: 4096x4096

Full traceback:
  File "renpy/ast.py", line 625, in eval_who
    return renpy.python.py_eval(who)
  File "renpy/python.py", line 1292, in py_eval
    return py_eval_bytecode(code, globals, locals)
  File "renpy/python.py", line 1285, in py_eval_bytecode
    return eval(bytecode, globals, locals)
  File "<none>", line 1, in <module>
NameError: name 'e' is not defined

During handling of the above exception, another exception occurred:

Traceback (most recent call last):
  File "game/script.rpy", line 27, in script
    e "You've created a new Ren'Py game."
  File "renpy/ast.py", line 2915, in execute
    Say.execute(self)
  File "renpy/ast.py", line 956, in execute
    who = eval_who(self.who, self.who_fast)
  File "renpy/ast.py", line 627, in eval_who
    raise Exception("Sayer '%s' is not defined." % who)
Exception: Sayer 'e' is not defined.

While running game code:
NameError: name 'e' is not defined

During handling of the above exception, another exception occurred:

Traceback (most recent call last):
  File "game/script.rpy", line 27, in script
    e "You've created a new Ren'Py game."
Exception: Sayer 'e' is not defined.
