I'm sorry, but an uncaught exception occurred.

While running game code:
NameError: name 'e' is not defined

During handling of the above exception, another exception occurred:

Traceback (most recent call last):
  File "game/script.rpy", line 27, in script
    e "You've created a new Ren'Py game."
Exception: Sayer 'e' is not defined.

-- Full Traceback ------------------------------------------------------------

Traceback (most recent call last):
  File "renpy/ast.py", line 625, in eval_who
    return renpy.python.py_eval(who)
           ~~~~~~~~~~~~~~~~~~~~^^^^^
  File "renpy/python.py", line 1292, in py_eval
    return py_eval_bytecode(code, globals, locals)
           ~~~~~~~~~~~~~~~~^^^^^^^^^^^^^^^^^^^^^^^
  File "renpy/python.py", line 1285, in py_eval_bytecode
    return eval(bytecode, globals, locals)
           ~~~~^^^^^^^^^^^^^^^^^^^^^^^^^^^
  File "<none>", line 1, in <module>
NameError: name 'e' is not defined

During handling of the above exception, another exception occurred:

Traceback (most recent call last):
  File "game/script.rpy", line 27, in script
    e "You've created a new Ren'Py game."
  File "renpy/ast.py", line 2915, in execute
    Say.execute(self)
    ~~~~~~~~~~~^^^^^^
  File "renpy/ast.py", line 956, in execute
    who = eval_who(self.who, self.who_fast)
          ~~~~~~~~^^^^^^^^^^^^^^^^^^^^^^^^^
  File "renpy/ast.py", line 627, in eval_who
    raise Exception("Sayer '%s' is not defined." % who)
Exception: Sayer 'e' is not defined.

Linux-6.6.88-08507-gc5e3cc23fa55-x86_64-with-glibc2.36 x86_64
Ren'Py 8.4.1.25072401
northriff VN 1.0
Sun Sep 28 13:02:04 2025
